<?xml version="1.0"?>
<robot name="warehouse_amr" xmlns:xacro="http://ros.org/wiki/xacro">
  
  <link name="base_footprint"/>
  <joint name="base_footprint_joint" type="fixed">
    <parent link="base_footprint"/>
    <child link="base_link"/>
    <origin xyz="0 0 0.15" rpy="0 0 0"/>
  </joint>

  <link name="base_link">
    <visual><geometry><box size="0.6 0.4 0.2"/></geometry><material name="blue"><color rgba="0 0 0.8 1"/></material></visual>
    <collision><geometry><box size="0.6 0.4 0.2"/></geometry></collision>
    <inertial><mass value="10.0"/><inertia ixx="0.1" ixy="0.0" ixz="0.0" iyy="0.1" iyz="0.0" izz="0.1"/></inertial>
  </link>

  <link name="left_wheel">
    <visual><geometry><cylinder radius="0.1" length="0.05"/></geometry></visual>
    <collision><geometry><cylinder radius="0.1" length="0.05"/></geometry></collision>
    <inertial><mass value="1.0"/><inertia ixx="0.01" ixy="0.0" ixz="0.0" iyy="0.01" iyz="0.0" izz="0.01"/></inertial>
  </link>
  <joint name="left_wheel_joint" type="continuous">
    <parent link="base_link"/><child link="left_wheel"/>
    <origin xyz="0 0.225 -0.05" rpy="-1.5707 0 0"/>
    <axis xyz="0 0 1"/>
  </joint>

  <link name="right_wheel">
    <visual><geometry><cylinder radius="0.1" length="0.05"/></geometry></visual>
    <collision><geometry><cylinder radius="0.1" length="0.05"/></geometry></collision>
    <inertial><mass value="1.0"/><inertia ixx="0.01" ixy="0.0" ixz="0.0" iyy="0.01" iyz="0.0" izz="0.01"/></inertial>
  </link>
  <joint name="right_wheel_joint" type="continuous">
    <parent link="base_link"/><child link="right_wheel"/>
    <origin xyz="0 -0.225 -0.05" rpy="-1.5707 0 0"/>
    <axis xyz="0 0 1"/>
  </joint>

  <link name="caster_wheel">
    <visual><geometry><sphere radius="0.05"/></geometry></visual>
    <collision><geometry><sphere radius="0.05"/></geometry></collision>
    <inertial><mass value="0.5"/><inertia ixx="0.001" ixy="0.0" ixz="0.0" iyy="0.001" iyz="0.0" izz="0.001"/></inertial>
  </link>
  <joint name="caster_joint" type="fixed">
    <parent link="base_link"/><child link="caster_wheel"/>
    <origin xyz="0.25 0 -0.1" rpy="0 0 0"/>
  </joint>

  <link name="laser_link">
    <visual><geometry><cylinder radius="0.05" length="0.05"/></geometry><material name="black"><color rgba="0 0 0 1"/></material></visual>
    <collision><geometry><cylinder radius="0.05" length="0.05"/></geometry></collision>
    <inertial><mass value="0.2"/><inertia ixx="0.001" ixy="0.0" ixz="0.0" iyy="0.001" iyz="0.0" izz="0.001"/></inertial>
  </link>
  <joint name="laser_joint" type="fixed">
    <parent link="base_link"/><child link="laser_link"/>
    <origin xyz="0.25 0 0.125" rpy="0 0 0"/>
  </joint>

  <gazebo reference="laser_link">
    <sensor name="lidar" type="gpu_lidar">
      <pose>0 0 0 0 0 0</pose>
      <topic>scan</topic>
      <update_rate>10</update_rate>
      <gz_frame_id>laser_link</gz_frame_id>
      <ray>
        <scan>
          <horizontal><samples>360</samples><resolution>1</resolution><min_angle>-3.14159</min_angle><max_angle>3.14159</max_angle></horizontal>
        </scan>
        <range><min>0.1</min><max>10.0</max><resolution>0.01</resolution></range>
      </ray>
      <always_on>true</always_on>
      <visualize>true</visualize>
    </sensor>
  </gazebo>

  <gazebo>
    <plugin filename="gz-sim-diff-drive-system" name="gz::sim::systems::DiffDrive">
      <left_joint>left_wheel_joint</left_joint>
      <right_joint>right_wheel_joint</right_joint>
      <wheel_separation>0.45</wheel_separation>
      <wheel_radius>0.1</wheel_radius>
      <odom_publish_frequency>30</odom_publish_frequency>
      <topic>cmd_vel</topic>
      <odom_topic>odom</odom_topic>
      <tf_topic>tf</tf_topic>
      <frame_id>odom</frame_id>
      <child_frame_id>base_footprint</child_frame_id>
    </plugin>
  </gazebo>
</robot>
